2024-09-10 19:21:17,681 ERROR: Exception on / [GET] [in /home/ubuntu/microblog/venv/lib/python3.10/site-packages/flask/app.py:838]
Traceback (most recent call last):
  File "/home/ubuntu/microblog/venv/lib/python3.10/site-packages/flask/app.py", line 1473, in wsgi_app
    response = self.full_dispatch_request()
  File "/home/ubuntu/microblog/venv/lib/python3.10/site-packages/flask/app.py", line 882, in full_dispatch_request
    rv = self.handle_user_exception(e)
  File "/home/ubuntu/microblog/venv/lib/python3.10/site-packages/flask/app.py", line 880, in full_dispatch_request
    rv = self.dispatch_request()
  File "/home/ubuntu/microblog/venv/lib/python3.10/site-packages/flask/app.py", line 865, in dispatch_request
    return self.ensure_sync(self.view_functions[rule.endpoint])(**view_args)  # type: ignore[no-any-return]
  File "/home/ubuntu/microblog/venv/lib/python3.10/site-packages/flask_login/utils.py", line 285, in decorated_view
    return current_app.login_manager.unauthorized()
  File "/home/ubuntu/microblog/venv/lib/python3.10/site-packages/flask_login/login_manager.py", line 196, in unauthorized
    redirect_url = make_login_url(login_view, next_url=request.url)
  File "/home/ubuntu/microblog/venv/lib/python3.10/site-packages/flask_login/utils.py", line 120, in login_url
    base = expand_login_view(login_view)
  File "/home/ubuntu/microblog/venv/lib/python3.10/site-packages/flask_login/utils.py", line 97, in expand_login_view
    return url_for(login_view)
  File "/home/ubuntu/microblog/venv/lib/python3.10/site-packages/flask/helpers.py", line 220, in url_for
    return current_app.url_for(
  File "/home/ubuntu/microblog/venv/lib/python3.10/site-packages/flask/app.py", line 1084, in url_for
    return self.handle_url_build_error(error, endpoint, values)
  File "/home/ubuntu/microblog/venv/lib/python3.10/site-packages/flask/app.py", line 1073, in url_for
    rv = url_adapter.build(  # type: ignore[union-attr]
  File "/home/ubuntu/microblog/venv/lib/python3.10/site-packages/werkzeug/routing/map.py", line 924, in build
    raise BuildError(endpoint, values, method, self)
werkzeug.routing.exceptions.BuildError: Could not build url for endpoint 'login'. Did you mean 'auth.login' instead?
2024-09-10 19:28:45,784 INFO: Microblog startup [in /home/ubuntu/microblog/app/__init__.py:60]
2024-09-10 19:29:08,263 ERROR: Exception on / [GET] [in /home/ubuntu/microblog/venv/lib/python3.10/site-packages/flask/app.py:838]
Traceback (most recent call last):
  File "/home/ubuntu/microblog/venv/lib/python3.10/site-packages/flask/app.py", line 1473, in wsgi_app
    response = self.full_dispatch_request()
  File "/home/ubuntu/microblog/venv/lib/python3.10/site-packages/flask/app.py", line 882, in full_dispatch_request
    rv = self.handle_user_exception(e)
  File "/home/ubuntu/microblog/venv/lib/python3.10/site-packages/flask/app.py", line 880, in full_dispatch_request
    rv = self.dispatch_request()
  File "/home/ubuntu/microblog/venv/lib/python3.10/site-packages/flask/app.py", line 865, in dispatch_request
    return self.ensure_sync(self.view_functions[rule.endpoint])(**view_args)  # type: ignore[no-any-return]
  File "/home/ubuntu/microblog/venv/lib/python3.10/site-packages/flask_login/utils.py", line 285, in decorated_view
    return current_app.login_manager.unauthorized()
  File "/home/ubuntu/microblog/venv/lib/python3.10/site-packages/flask_login/login_manager.py", line 196, in unauthorized
    redirect_url = make_login_url(login_view, next_url=request.url)
  File "/home/ubuntu/microblog/venv/lib/python3.10/site-packages/flask_login/utils.py", line 120, in login_url
    base = expand_login_view(login_view)
  File "/home/ubuntu/microblog/venv/lib/python3.10/site-packages/flask_login/utils.py", line 97, in expand_login_view
    return url_for(login_view)
  File "/home/ubuntu/microblog/venv/lib/python3.10/site-packages/flask/helpers.py", line 220, in url_for
    return current_app.url_for(
  File "/home/ubuntu/microblog/venv/lib/python3.10/site-packages/flask/app.py", line 1084, in url_for
    return self.handle_url_build_error(error, endpoint, values)
  File "/home/ubuntu/microblog/venv/lib/python3.10/site-packages/flask/app.py", line 1073, in url_for
    rv = url_adapter.build(  # type: ignore[union-attr]
  File "/home/ubuntu/microblog/venv/lib/python3.10/site-packages/werkzeug/routing/map.py", line 924, in build
    raise BuildError(endpoint, values, method, self)
werkzeug.routing.exceptions.BuildError: Could not build url for endpoint 'login'. Did you mean 'auth.login' instead?
2024-09-10 19:36:38,665 INFO: Microblog startup [in /home/ubuntu/microblog/app/__init__.py:60]
2024-09-10 19:36:53,803 ERROR: Exception on /index [GET] [in /home/ubuntu/microblog/venv/lib/python3.10/site-packages/flask/app.py:838]
Traceback (most recent call last):
  File "/home/ubuntu/microblog/venv/lib/python3.10/site-packages/flask/app.py", line 1473, in wsgi_app
    response = self.full_dispatch_request()
  File "/home/ubuntu/microblog/venv/lib/python3.10/site-packages/flask/app.py", line 882, in full_dispatch_request
    rv = self.handle_user_exception(e)
  File "/home/ubuntu/microblog/venv/lib/python3.10/site-packages/flask/app.py", line 880, in full_dispatch_request
    rv = self.dispatch_request()
  File "/home/ubuntu/microblog/venv/lib/python3.10/site-packages/flask/app.py", line 865, in dispatch_request
    return self.ensure_sync(self.view_functions[rule.endpoint])(**view_args)  # type: ignore[no-any-return]
  File "/home/ubuntu/microblog/venv/lib/python3.10/site-packages/flask_login/utils.py", line 285, in decorated_view
    return current_app.login_manager.unauthorized()
  File "/home/ubuntu/microblog/venv/lib/python3.10/site-packages/flask_login/login_manager.py", line 196, in unauthorized
    redirect_url = make_login_url(login_view, next_url=request.url)
  File "/home/ubuntu/microblog/venv/lib/python3.10/site-packages/flask_login/utils.py", line 120, in login_url
    base = expand_login_view(login_view)
  File "/home/ubuntu/microblog/venv/lib/python3.10/site-packages/flask_login/utils.py", line 97, in expand_login_view
    return url_for(login_view)
  File "/home/ubuntu/microblog/venv/lib/python3.10/site-packages/flask/helpers.py", line 220, in url_for
    return current_app.url_for(
  File "/home/ubuntu/microblog/venv/lib/python3.10/site-packages/flask/app.py", line 1084, in url_for
    return self.handle_url_build_error(error, endpoint, values)
  File "/home/ubuntu/microblog/venv/lib/python3.10/site-packages/flask/app.py", line 1073, in url_for
    rv = url_adapter.build(  # type: ignore[union-attr]
  File "/home/ubuntu/microblog/venv/lib/python3.10/site-packages/werkzeug/routing/map.py", line 924, in build
    raise BuildError(endpoint, values, method, self)
werkzeug.routing.exceptions.BuildError: Could not build url for endpoint 'login'. Did you mean 'auth.login' instead?
2024-09-10 19:42:37,467 INFO: Microblog startup [in /home/ubuntu/microblog/app/__init__.py:60]
2024-09-10 19:42:46,388 ERROR: Exception on / [GET] [in /home/ubuntu/microblog/venv/lib/python3.10/site-packages/flask/app.py:838]
Traceback (most recent call last):
  File "/home/ubuntu/microblog/venv/lib/python3.10/site-packages/flask/app.py", line 1473, in wsgi_app
    response = self.full_dispatch_request()
  File "/home/ubuntu/microblog/venv/lib/python3.10/site-packages/flask/app.py", line 882, in full_dispatch_request
    rv = self.handle_user_exception(e)
  File "/home/ubuntu/microblog/venv/lib/python3.10/site-packages/flask/app.py", line 880, in full_dispatch_request
    rv = self.dispatch_request()
  File "/home/ubuntu/microblog/venv/lib/python3.10/site-packages/flask/app.py", line 865, in dispatch_request
    return self.ensure_sync(self.view_functions[rule.endpoint])(**view_args)  # type: ignore[no-any-return]
  File "/home/ubuntu/microblog/venv/lib/python3.10/site-packages/flask_login/utils.py", line 285, in decorated_view
    return current_app.login_manager.unauthorized()
  File "/home/ubuntu/microblog/venv/lib/python3.10/site-packages/flask_login/login_manager.py", line 196, in unauthorized
    redirect_url = make_login_url(login_view, next_url=request.url)
  File "/home/ubuntu/microblog/venv/lib/python3.10/site-packages/flask_login/utils.py", line 120, in login_url
    base = expand_login_view(login_view)
  File "/home/ubuntu/microblog/venv/lib/python3.10/site-packages/flask_login/utils.py", line 97, in expand_login_view
    return url_for(login_view)
  File "/home/ubuntu/microblog/venv/lib/python3.10/site-packages/flask/helpers.py", line 220, in url_for
    return current_app.url_for(
  File "/home/ubuntu/microblog/venv/lib/python3.10/site-packages/flask/app.py", line 1084, in url_for
    return self.handle_url_build_error(error, endpoint, values)
  File "/home/ubuntu/microblog/venv/lib/python3.10/site-packages/flask/app.py", line 1073, in url_for
    rv = url_adapter.build(  # type: ignore[union-attr]
  File "/home/ubuntu/microblog/venv/lib/python3.10/site-packages/werkzeug/routing/map.py", line 924, in build
    raise BuildError(endpoint, values, method, self)
werkzeug.routing.exceptions.BuildError: Could not build url for endpoint 'login'. Did you mean 'auth.login' instead?
2024-09-10 19:44:49,345 INFO: Microblog startup [in /home/ubuntu/microblog/app/__init__.py:60]
