2024-09-10 19:46:40,267 ERROR: Exception on /auth/reset_password_request [POST] [in /home/ubuntu/microblog/venv/lib/python3.10/site-packages/flask/app.py:838]
Traceback (most recent call last):
  File "/home/ubuntu/microblog/venv/lib/python3.10/site-packages/flask/app.py", line 1473, in wsgi_app
    response = self.full_dispatch_request()
  File "/home/ubuntu/microblog/venv/lib/python3.10/site-packages/flask/app.py", line 882, in full_dispatch_request
    rv = self.handle_user_exception(e)
  File "/home/ubuntu/microblog/venv/lib/python3.10/site-packages/flask/app.py", line 880, in full_dispatch_request
    rv = self.dispatch_request()
  File "/home/ubuntu/microblog/venv/lib/python3.10/site-packages/flask/app.py", line 865, in dispatch_request
    return self.ensure_sync(self.view_functions[rule.endpoint])(**view_args)  # type: ignore[no-any-return]
  File "/home/ubuntu/microblog/app/auth/routes.py", line 56, in reset_password_request
    send_password_reset_email(user)
  File "/home/ubuntu/microblog/app/auth/email.py", line 10, in send_password_reset_email
    text_body=render_template('email/reset_password.txt',
  File "/home/ubuntu/microblog/venv/lib/python3.10/site-packages/flask/templating.py", line 150, in render_template
    return _render(app, template, context)
  File "/home/ubuntu/microblog/venv/lib/python3.10/site-packages/flask/templating.py", line 131, in _render
    rv = template.render(context)
  File "/home/ubuntu/microblog/venv/lib/python3.10/site-packages/jinja2/environment.py", line 1304, in render
    self.environment.handle_exception()
  File "/home/ubuntu/microblog/venv/lib/python3.10/site-packages/jinja2/environment.py", line 939, in handle_exception
    raise rewrite_traceback_stack(source=source)
  File "/home/ubuntu/microblog/app/templates/email/reset_password.txt", line 4, in top-level template code
    {{ url_for('reset_password', token=token, _external=True) }}
  File "/home/ubuntu/microblog/venv/lib/python3.10/site-packages/flask/app.py", line 1084, in url_for
    return self.handle_url_build_error(error, endpoint, values)
  File "/home/ubuntu/microblog/venv/lib/python3.10/site-packages/flask/app.py", line 1073, in url_for
    rv = url_adapter.build(  # type: ignore[union-attr]
  File "/home/ubuntu/microblog/venv/lib/python3.10/site-packages/werkzeug/routing/map.py", line 924, in build
    raise BuildError(endpoint, values, method, self)
werkzeug.routing.exceptions.BuildError: Could not build url for endpoint 'reset_password' with values ['token']. Did you mean 'auth.reset_password' instead?
2024-09-10 19:48:12,411 INFO: Microblog startup [in /home/ubuntu/microblog/app/__init__.py:60]
2024-09-10 19:48:22,751 ERROR: Exception on /auth/reset_password_request [POST] [in /home/ubuntu/microblog/venv/lib/python3.10/site-packages/flask/app.py:838]
Traceback (most recent call last):
  File "/home/ubuntu/microblog/venv/lib/python3.10/site-packages/flask/app.py", line 1473, in wsgi_app
    response = self.full_dispatch_request()
  File "/home/ubuntu/microblog/venv/lib/python3.10/site-packages/flask/app.py", line 882, in full_dispatch_request
    rv = self.handle_user_exception(e)
  File "/home/ubuntu/microblog/venv/lib/python3.10/site-packages/flask/app.py", line 880, in full_dispatch_request
    rv = self.dispatch_request()
  File "/home/ubuntu/microblog/venv/lib/python3.10/site-packages/flask/app.py", line 865, in dispatch_request
    return self.ensure_sync(self.view_functions[rule.endpoint])(**view_args)  # type: ignore[no-any-return]
  File "/home/ubuntu/microblog/app/auth/routes.py", line 56, in reset_password_request
    send_password_reset_email(user)
  File "/home/ubuntu/microblog/app/auth/email.py", line 12, in send_password_reset_email
    html_body=render_template('email/reset_password.html',
  File "/home/ubuntu/microblog/venv/lib/python3.10/site-packages/flask/templating.py", line 150, in render_template
    return _render(app, template, context)
  File "/home/ubuntu/microblog/venv/lib/python3.10/site-packages/flask/templating.py", line 131, in _render
    rv = template.render(context)
  File "/home/ubuntu/microblog/venv/lib/python3.10/site-packages/jinja2/environment.py", line 1304, in render
    self.environment.handle_exception()
  File "/home/ubuntu/microblog/venv/lib/python3.10/site-packages/jinja2/environment.py", line 939, in handle_exception
    raise rewrite_traceback_stack(source=source)
  File "/home/ubuntu/microblog/app/templates/email/reset_password.html", line 10, in top-level template code
    <p>{{ url_for('reset_password', token=token, _external=True) }}</p>
  File "/home/ubuntu/microblog/venv/lib/python3.10/site-packages/flask/app.py", line 1084, in url_for
    return self.handle_url_build_error(error, endpoint, values)
  File "/home/ubuntu/microblog/venv/lib/python3.10/site-packages/flask/app.py", line 1073, in url_for
    rv = url_adapter.build(  # type: ignore[union-attr]
  File "/home/ubuntu/microblog/venv/lib/python3.10/site-packages/werkzeug/routing/map.py", line 924, in build
    raise BuildError(endpoint, values, method, self)
werkzeug.routing.exceptions.BuildError: Could not build url for endpoint 'reset_password' with values ['token']. Did you mean 'auth.reset_password' instead?
2024-09-10 19:49:15,035 INFO: Microblog startup [in /home/ubuntu/microblog/app/__init__.py:60]
2024-09-10 23:10:36,448 INFO: Microblog startup [in /home/ubuntu/microblog/app/__init__.py:63]
2024-09-10 23:12:59,326 INFO: Microblog startup [in /home/ubuntu/microblog/app/__init__.py:63]
2024-09-10 23:13:16,375 ERROR: Exception on /auth/login [GET] [in /home/ubuntu/microblog/venv/lib/python3.10/site-packages/flask/app.py:838]
Traceback (most recent call last):
  File "/home/ubuntu/microblog/venv/lib/python3.10/site-packages/flask/app.py", line 1473, in wsgi_app
    response = self.full_dispatch_request()
  File "/home/ubuntu/microblog/venv/lib/python3.10/site-packages/flask/app.py", line 882, in full_dispatch_request
    rv = self.handle_user_exception(e)
  File "/home/ubuntu/microblog/venv/lib/python3.10/site-packages/flask/app.py", line 880, in full_dispatch_request
    rv = self.dispatch_request()
  File "/home/ubuntu/microblog/venv/lib/python3.10/site-packages/flask/app.py", line 865, in dispatch_request
    return self.ensure_sync(self.view_functions[rule.endpoint])(**view_args)  # type: ignore[no-any-return]
  File "/home/ubuntu/microblog/app/auth/routes.py", line 26, in login
    return render_template('auth/login.html',  title='Sign In', form=form)
  File "/home/ubuntu/microblog/venv/lib/python3.10/site-packages/flask/templating.py", line 150, in render_template
    return _render(app, template, context)
  File "/home/ubuntu/microblog/venv/lib/python3.10/site-packages/flask/templating.py", line 131, in _render
    rv = template.render(context)
  File "/home/ubuntu/microblog/venv/lib/python3.10/site-packages/jinja2/environment.py", line 1304, in render
    self.environment.handle_exception()
  File "/home/ubuntu/microblog/venv/lib/python3.10/site-packages/jinja2/environment.py", line 939, in handle_exception
    raise rewrite_traceback_stack(source=source)
  File "/home/ubuntu/microblog/app/templates/auth/login.html", line 1, in top-level template code
    {% extends "base.html" %}
  File "/home/ubuntu/microblog/app/templates/base.html", line 30, in top-level template code
    <a class="nav-link" aria-current="page" href="{{ url_for('main.explore') }}">Explore</a>
  File "/home/ubuntu/microblog/venv/lib/python3.10/site-packages/flask/app.py", line 1084, in url_for
    return self.handle_url_build_error(error, endpoint, values)
  File "/home/ubuntu/microblog/venv/lib/python3.10/site-packages/flask/app.py", line 1073, in url_for
    rv = url_adapter.build(  # type: ignore[union-attr]
  File "/home/ubuntu/microblog/venv/lib/python3.10/site-packages/werkzeug/routing/map.py", line 924, in build
    raise BuildError(endpoint, values, method, self)
werkzeug.routing.exceptions.BuildError: Could not build url for endpoint 'main.explore'. Did you mean 'explore' instead?
2024-09-10 23:14:38,652 INFO: Microblog startup [in /home/ubuntu/microblog/app/__init__.py:63]
2024-09-10 23:15:47,003 ERROR: Exception on /auth/login [POST] [in /home/ubuntu/microblog/venv/lib/python3.10/site-packages/flask/app.py:838]
Traceback (most recent call last):
  File "/home/ubuntu/microblog/venv/lib/python3.10/site-packages/flask/app.py", line 1473, in wsgi_app
    response = self.full_dispatch_request()
  File "/home/ubuntu/microblog/venv/lib/python3.10/site-packages/flask/app.py", line 882, in full_dispatch_request
    rv = self.handle_user_exception(e)
  File "/home/ubuntu/microblog/venv/lib/python3.10/site-packages/flask/app.py", line 880, in full_dispatch_request
    rv = self.dispatch_request()
  File "/home/ubuntu/microblog/venv/lib/python3.10/site-packages/flask/app.py", line 865, in dispatch_request
    return self.ensure_sync(self.view_functions[rule.endpoint])(**view_args)  # type: ignore[no-any-return]
  File "/home/ubuntu/microblog/app/auth/routes.py", line 24, in login
    next_page = url_for('index')
  File "/home/ubuntu/microblog/venv/lib/python3.10/site-packages/flask/helpers.py", line 220, in url_for
    return current_app.url_for(
  File "/home/ubuntu/microblog/venv/lib/python3.10/site-packages/flask/app.py", line 1084, in url_for
    return self.handle_url_build_error(error, endpoint, values)
  File "/home/ubuntu/microblog/venv/lib/python3.10/site-packages/flask/app.py", line 1073, in url_for
    rv = url_adapter.build(  # type: ignore[union-attr]
  File "/home/ubuntu/microblog/venv/lib/python3.10/site-packages/werkzeug/routing/map.py", line 924, in build
    raise BuildError(endpoint, values, method, self)
werkzeug.routing.exceptions.BuildError: Could not build url for endpoint 'index'. Did you mean 'main.index' instead?
2024-09-10 23:18:03,394 INFO: Microblog startup [in /home/ubuntu/microblog/app/__init__.py:63]
