2024-09-07 04:25:34,185 ERROR: Exception on /edit_profile [POST] [in /home/ubuntu/microblog/venv/lib/python3.10/site-packages/flask/app.py:838]
Traceback (most recent call last):
  File "/home/ubuntu/microblog/venv/lib/python3.10/site-packages/sqlalchemy/engine/base.py", line 1967, in _exec_single_context
    self.dialect.do_execute(
  File "/home/ubuntu/microblog/venv/lib/python3.10/site-packages/sqlalchemy/engine/default.py", line 941, in do_execute
    cursor.execute(statement, parameters)
sqlite3.IntegrityError: UNIQUE constraint failed: user.username

The above exception was the direct cause of the following exception:

Traceback (most recent call last):
  File "/home/ubuntu/microblog/venv/lib/python3.10/site-packages/flask/app.py", line 1473, in wsgi_app
    response = self.full_dispatch_request()
  File "/home/ubuntu/microblog/venv/lib/python3.10/site-packages/flask/app.py", line 882, in full_dispatch_request
    rv = self.handle_user_exception(e)
  File "/home/ubuntu/microblog/venv/lib/python3.10/site-packages/flask/app.py", line 880, in full_dispatch_request
    rv = self.dispatch_request()
  File "/home/ubuntu/microblog/venv/lib/python3.10/site-packages/flask/app.py", line 865, in dispatch_request
    return self.ensure_sync(self.view_functions[rule.endpoint])(**view_args)  # type: ignore[no-any-return]
  File "/home/ubuntu/microblog/venv/lib/python3.10/site-packages/flask_login/utils.py", line 290, in decorated_view
    return current_app.ensure_sync(func)(*args, **kwargs)
  File "/home/ubuntu/microblog/app/routes.py", line 99, in edit_profile
    db.session.commit()
  File "/home/ubuntu/microblog/venv/lib/python3.10/site-packages/sqlalchemy/orm/scoping.py", line 597, in commit
    return self._proxied.commit()
  File "/home/ubuntu/microblog/venv/lib/python3.10/site-packages/sqlalchemy/orm/session.py", line 2028, in commit
    trans.commit(_to_root=True)
  File "<string>", line 2, in commit
  File "/home/ubuntu/microblog/venv/lib/python3.10/site-packages/sqlalchemy/orm/state_changes.py", line 139, in _go
    ret_value = fn(self, *arg, **kw)
  File "/home/ubuntu/microblog/venv/lib/python3.10/site-packages/sqlalchemy/orm/session.py", line 1313, in commit
    self._prepare_impl()
  File "<string>", line 2, in _prepare_impl
  File "/home/ubuntu/microblog/venv/lib/python3.10/site-packages/sqlalchemy/orm/state_changes.py", line 139, in _go
    ret_value = fn(self, *arg, **kw)
  File "/home/ubuntu/microblog/venv/lib/python3.10/site-packages/sqlalchemy/orm/session.py", line 1288, in _prepare_impl
    self.session.flush()
  File "/home/ubuntu/microblog/venv/lib/python3.10/site-packages/sqlalchemy/orm/session.py", line 4352, in flush
    self._flush(objects)
  File "/home/ubuntu/microblog/venv/lib/python3.10/site-packages/sqlalchemy/orm/session.py", line 4487, in _flush
    with util.safe_reraise():
  File "/home/ubuntu/microblog/venv/lib/python3.10/site-packages/sqlalchemy/util/langhelpers.py", line 146, in __exit__
    raise exc_value.with_traceback(exc_tb)
  File "/home/ubuntu/microblog/venv/lib/python3.10/site-packages/sqlalchemy/orm/session.py", line 4448, in _flush
    flush_context.execute()
  File "/home/ubuntu/microblog/venv/lib/python3.10/site-packages/sqlalchemy/orm/unitofwork.py", line 466, in execute
    rec.execute(self)
  File "/home/ubuntu/microblog/venv/lib/python3.10/site-packages/sqlalchemy/orm/unitofwork.py", line 642, in execute
    util.preloaded.orm_persistence.save_obj(
  File "/home/ubuntu/microblog/venv/lib/python3.10/site-packages/sqlalchemy/orm/persistence.py", line 85, in save_obj
    _emit_update_statements(
  File "/home/ubuntu/microblog/venv/lib/python3.10/site-packages/sqlalchemy/orm/persistence.py", line 912, in _emit_update_statements
    c = connection.execute(
  File "/home/ubuntu/microblog/venv/lib/python3.10/site-packages/sqlalchemy/engine/base.py", line 1418, in execute
    return meth(
  File "/home/ubuntu/microblog/venv/lib/python3.10/site-packages/sqlalchemy/sql/elements.py", line 515, in _execute_on_connection
    return connection._execute_clauseelement(
  File "/home/ubuntu/microblog/venv/lib/python3.10/site-packages/sqlalchemy/engine/base.py", line 1640, in _execute_clauseelement
    ret = self._execute_context(
  File "/home/ubuntu/microblog/venv/lib/python3.10/site-packages/sqlalchemy/engine/base.py", line 1846, in _execute_context
    return self._exec_single_context(
  File "/home/ubuntu/microblog/venv/lib/python3.10/site-packages/sqlalchemy/engine/base.py", line 1986, in _exec_single_context
    self._handle_dbapi_exception(
  File "/home/ubuntu/microblog/venv/lib/python3.10/site-packages/sqlalchemy/engine/base.py", line 2355, in _handle_dbapi_exception
    raise sqlalchemy_exception.with_traceback(exc_info[2]) from e
  File "/home/ubuntu/microblog/venv/lib/python3.10/site-packages/sqlalchemy/engine/base.py", line 1967, in _exec_single_context
    self.dialect.do_execute(
  File "/home/ubuntu/microblog/venv/lib/python3.10/site-packages/sqlalchemy/engine/default.py", line 941, in do_execute
    cursor.execute(statement, parameters)
sqlalchemy.exc.IntegrityError: (sqlite3.IntegrityError) UNIQUE constraint failed: user.username
[SQL: UPDATE user SET username=? WHERE user.id = ?]
[parameters: ('Bob1', 1)]
(Background on this error at: https://sqlalche.me/e/20/gkpj)
2024-09-07 18:52:29,577 INFO: Microblog startup [in /home/ubuntu/microblog/app/__init__.py:45]
2024-09-07 18:53:38,261 INFO: Microblog startup [in /home/ubuntu/microblog/app/__init__.py:45]
2024-09-07 19:04:48,798 INFO: Microblog startup [in /home/ubuntu/microblog/app/__init__.py:45]
2024-09-07 19:07:32,095 INFO: Microblog startup [in /home/ubuntu/microblog/app/__init__.py:45]
2024-09-07 19:20:39,298 INFO: Microblog startup [in /home/ubuntu/microblog/app/__init__.py:45]
2024-09-07 19:24:40,947 INFO: Microblog startup [in /home/ubuntu/microblog/app/__init__.py:45]
2024-09-07 19:25:51,291 INFO: Microblog startup [in /home/ubuntu/microblog/app/__init__.py:45]
2024-09-07 19:40:29,660 INFO: Microblog startup [in /home/ubuntu/microblog/app/__init__.py:45]
2024-09-07 19:44:02,648 INFO: Microblog startup [in /home/ubuntu/microblog/app/__init__.py:45]
2024-09-07 19:45:14,383 INFO: Microblog startup [in /home/ubuntu/microblog/app/__init__.py:45]
2024-09-07 19:46:24,412 INFO: Microblog startup [in /home/ubuntu/microblog/app/__init__.py:45]
2024-09-07 19:51:47,031 INFO: Microblog startup [in /home/ubuntu/microblog/app/__init__.py:45]
2024-09-07 19:54:22,004 INFO: Microblog startup [in /home/ubuntu/microblog/app/__init__.py:45]
2024-09-07 19:56:04,630 INFO: Microblog startup [in /home/ubuntu/microblog/app/__init__.py:45]
2024-09-07 21:59:07,110 INFO: Microblog startup [in /home/ubuntu/microblog/app/__init__.py:45]
2024-09-07 22:09:28,430 INFO: Microblog startup [in /home/ubuntu/microblog/app/__init__.py:45]
2024-09-07 22:14:36,604 INFO: Microblog startup [in /home/ubuntu/microblog/app/__init__.py:45]
2024-09-07 22:15:39,617 INFO: Microblog startup [in /home/ubuntu/microblog/app/__init__.py:45]
2024-09-07 22:24:22,487 INFO: Microblog startup [in /home/ubuntu/microblog/app/__init__.py:45]
2024-09-08 19:48:50,033 INFO: Microblog startup [in /home/ubuntu/microblog/app/__init__.py:45]
2024-09-08 19:49:10,110 INFO: Microblog startup [in /home/ubuntu/microblog/app/__init__.py:45]
2024-09-08 21:18:35,979 INFO: Microblog startup [in /home/ubuntu/microblog/app/__init__.py:45]
2024-09-08 21:19:06,011 ERROR: Exception on /reset_password_request [GET] [in /home/ubuntu/microblog/venv/lib/python3.10/site-packages/flask/app.py:838]
Traceback (most recent call last):
  File "/home/ubuntu/microblog/venv/lib/python3.10/site-packages/flask/app.py", line 1473, in wsgi_app
    response = self.full_dispatch_request()
  File "/home/ubuntu/microblog/venv/lib/python3.10/site-packages/flask/app.py", line 882, in full_dispatch_request
    rv = self.handle_user_exception(e)
  File "/home/ubuntu/microblog/venv/lib/python3.10/site-packages/flask/app.py", line 880, in full_dispatch_request
    rv = self.dispatch_request()
  File "/home/ubuntu/microblog/venv/lib/python3.10/site-packages/flask/app.py", line 865, in dispatch_request
    return self.ensure_sync(self.view_functions[rule.endpoint])(**view_args)  # type: ignore[no-any-return]
  File "/home/ubuntu/microblog/app/routes.py", line 173, in reset_password_request
    return render_template('reset_password_request.html', title='Reset Password', form=form)
  File "/home/ubuntu/microblog/venv/lib/python3.10/site-packages/flask/templating.py", line 149, in render_template
    template = app.jinja_env.get_or_select_template(template_name_or_list)
  File "/home/ubuntu/microblog/venv/lib/python3.10/site-packages/jinja2/environment.py", line 1084, in get_or_select_template
    return self.get_template(template_name_or_list, parent, globals)
  File "/home/ubuntu/microblog/venv/lib/python3.10/site-packages/jinja2/environment.py", line 1013, in get_template
    return self._load_template(name, globals)
  File "/home/ubuntu/microblog/venv/lib/python3.10/site-packages/jinja2/environment.py", line 972, in _load_template
    template = self.loader.load(self, name, self.make_globals(globals))
  File "/home/ubuntu/microblog/venv/lib/python3.10/site-packages/jinja2/loaders.py", line 138, in load
    code = environment.compile(source, name, filename)
  File "/home/ubuntu/microblog/venv/lib/python3.10/site-packages/jinja2/environment.py", line 768, in compile
    self.handle_exception(source=source_hint)
  File "/home/ubuntu/microblog/venv/lib/python3.10/site-packages/jinja2/environment.py", line 939, in handle_exception
    raise rewrite_traceback_stack(source=source)
  File "/home/ubuntu/microblog/app/templates/reset_password_request.html", line 9, in template
    {{ form.email{size=64) }}<br>
jinja2.exceptions.TemplateSyntaxError: expected token 'end of print statement', got '{'
2024-09-08 21:22:35,656 INFO: Microblog startup [in /home/ubuntu/microblog/app/__init__.py:45]
